<?xml version="1.0" ?>
<!-- =================================================================================== -->
<!-- |    This document was autogenerated by xacro from /root/catkin_ws/src/millihexapod/robot/millihex_description.xacro | -->
<!-- |    EDITING THIS FILE BY HAND IS NOT RECOMMENDED                                 | -->
<!-- =================================================================================== -->
<!-- Generate URDF: -->
<!-- rosrun xacro xacro millihex_description.xacro > millihex_description.urdf -->
<robot name="millihex">
    <!-- PCB thickness (m) -->
    <!-- (kg) -->
    <!-- (kg) -->
    <!-- (kg) -->
    <!-- (kg) -->
    <!-- (kg) -->
    <!-- (kg) -->
    <!-- Friction coefficient 2 -->
    <!-- (N*m) -->
    <!-- Color Definitions -->
    <material name="Black">
        <color rgba="0.0 0.0 0.0 1.0" />
    </material>
    <material name="Orange">
        <color rgba="0.98 0.41 0.055 1.0" />
    </material>
    <material name="White">
        <color rgba="0.0 0.0 0.0 0.0" />
    </material>
    <!-- Dummy Base Link to support KDL -->
    <link name="base_link" />
    <!-- Thorax Geometry -->
    <link name="thorax">
        <inertial>
            <origin rpy="0 0 0" xyz="0 0 0" />
            <mass value="0.013600000000000003" />
            <inertia ixx="4.578666666666667e-07" ixy="0" ixz="0" iyy="3.2757866666666674e-05" iyz="0" izz="3.3206666666666675e-05" />
        </inertial>
        <collision>
            <origin rpy="0 0 0" xyz="0 0 0" />
            <geometry>
                <box size="0.17 0.02 0.002" />
            </geometry>
        </collision>
        <visual>
            <origin rpy="0 0 0" xyz="0 0 0" />
            <geometry>
                <box size="0.17 0.02 0.002" />
            </geometry>
            <material name="Orange" />
        </visual>
    </link>
    <!-- Gazebo properties -->
    <gazebo reference="thorax">
        <kp>100000.0</kp>
        <kd>1.0</kd>
        <mu1>100.0</mu1>
        <mu2>100.0</mu2>
        <material>Gazebo/Orange</material>
        <plugin name="gazebo_ros_control">
            <robotNamespace>/</robotNamespace>
        </plugin>
    </gazebo>
    <!-- Join Base Link and Thorax -->
    <joint name="base_joint" type="fixed">
        <parent link="base_link" />
        <child link="thorax" />
    </joint>
    <!-- Coxa Geometry -->
    <link name="leg1_coxa">
        <inertial>
            <origin rpy="0 0 0" xyz="0 0 0" />
            <mass value="0.0009" />
            <inertia ixx="1.7174999999999997e-08" ixy="0" ixz="0" iyy="1.7174999999999997e-08" iyz="0" izz="3.3749999999999995e-08" />
        </inertial>
        <collision>
            <origin rpy="0 0 0" xyz="0 0.0075 0" />
            <geometry>
                <box size="0.015 0.015 0.002" />
            </geometry>
        </collision>
        <visual>
            <origin rpy="0 0 0" xyz="0 0.0075 0" />
            <geometry>
                <box size="0.015 0.015 0.002" />
            </geometry>
            <material name="Black" />
        </visual>
    </link>
    <!-- Gazebo properties -->
    <gazebo reference="leg1_coxa">
        <kp>100000.0</kp>
        <kd>1.0</kd>
        <mu1>100.0</mu1>
        <mu2>100.0</mu2>
        <material>Gazebo/Black</material>
    </gazebo>
    <!-- Joint Link Geometry -->
    <link name="leg1_joint_link1">
        <inertial>
            <origin rpy="0 0 0" xyz="0 0 0" />
            <mass value="9.424777960769378e-05" />
            <inertia ixx="1.7907078125461817e-09" ixy="0" ixz="0" iyy="1.7907078125461817e-09" iyz="0" izz="4.712388980384689e-11" />
        </inertial>
        <collision>
            <origin rpy="0 1.5707963267948966 0.0" xyz="0 0 0" />
            <geometry>
                <cylinder length="0.015" radius="0.001" />
            </geometry>
        </collision>
        <visual>
            <origin rpy="0 1.5707963267948966 0.0" xyz="0 0 0" />
            <geometry>
                <cylinder length="0.015" radius="0.001" />
            </geometry>
            <material name="White" />
        </visual>
    </link>
    <!-- Gazebo properties -->
    <gazebo reference="leg1_joint_link1">
        <kp>100000.0</kp>
        <kd>1.0</kd>
        <mu1>100.0</mu1>
        <mu2>100.0</mu2>
        <material>Gazebo/White</material>
    </gazebo>
    <!-- Joint 1 -->
    <joint name="leg1_joint1" type="revolute">
        <parent link="leg1_coxa" />
        <child link="leg1_joint_link1" />
        <origin rpy="0 0 0" xyz="0 0.016 0" />
        <dynamics damping="0.0" friction="0.0" />
        <limit effort="1.0" lower="-1.5707963267948966" upper="1.5707963267948966" velocity="1.0" />
        <axis xyz="1 0 0" />
    </joint>
    <transmission name="leg1_joint1_tran">
        <type>transmission_interface/SimpleTransmission</type>
        <joint name="leg1_joint1">
            <hardwareInterface>hardware_interface/EffortJointInterface</hardwareInterface>
        </joint>
        <actuator name="leg1_joint1_motor">
            <hardwareInterface>hardware_interface/EffortJointInterface</hardwareInterface>
            <mechanicalReduction>1</mechanicalReduction>
        </actuator>
    </transmission>
    <!-- Femur (Leg Link 1) Geometry -->
    <link name="leg1_link1">
        <inertial>
            <origin rpy="0 0 0" xyz="0 0 0" />
            <mass value="0.0018" />
            <inertia ixx="1.3559999999999997e-07" ixy="0" ixz="0" iyy="3.434999999999999e-08" iyz="0" izz="1.6874999999999997e-07" />
        </inertial>
        <collision>
            <origin rpy="0 0 0" xyz="0 0.016 0" />
            <geometry>
                <box size="0.015 0.03 0.002" />
            </geometry>
        </collision>
        <visual>
            <origin rpy="0 0 0" xyz="0 0.016 0" />
            <geometry>
                <box size="0.015 0.03 0.002" />
            </geometry>
            <material name="Orange" />
        </visual>
    </link>
    <!-- Gazebo properties -->
    <gazebo reference="leg1_link1">
        <kp>100000.0</kp>
        <kd>1.0</kd>
        <mu1>100.0</mu1>
        <mu2>100.0</mu2>
        <material>Gazebo/Orange</material>
    </gazebo>
    <!-- Fixed Joint 1 -->
    <joint name="leg1_fixed_joint1" type="fixed">
        <parent link="leg1_joint_link1" />
        <child link="leg1_link1" />
        <origin rpy="0 0 0" xyz="0 0 0" />
    </joint>
    <!-- Joint Link Geometry -->
    <link name="leg1_joint_link2">
        <inertial>
            <origin rpy="0 0 0" xyz="0 0 0" />
            <mass value="9.424777960769378e-05" />
            <inertia ixx="1.7907078125461817e-09" ixy="0" ixz="0" iyy="1.7907078125461817e-09" iyz="0" izz="4.712388980384689e-11" />
        </inertial>
        <collision>
            <origin rpy="0 1.5707963267948966 1.5707963267948966" xyz="0 0 0" />
            <geometry>
                <cylinder length="0.015" radius="0.001" />
            </geometry>
        </collision>
        <visual>
            <origin rpy="0 1.5707963267948966 1.5707963267948966" xyz="0 0 0" />
            <geometry>
                <cylinder length="0.015" radius="0.001" />
            </geometry>
            <material name="White" />
        </visual>
    </link>
    <!-- Gazebo properties -->
    <gazebo reference="leg1_joint_link2">
        <kp>100000.0</kp>
        <kd>1.0</kd>
        <mu1>100.0</mu1>
        <mu2>100.0</mu2>
        <material>Gazebo/White</material>
    </gazebo>
    <!-- Joint 2 -->
    <joint name="leg1_joint2" type="revolute">
        <parent link="leg1_link1" />
        <child link="leg1_joint_link2" />
        <origin rpy="0 0 0" xyz="-0.0085                 0.0235 0" />
        <dynamics damping="0.0" friction="0.0" />
        <limit effort="1.0" lower="-1.5707963267948966" upper="1.5707963267948966" velocity="1.0" />
        <axis xyz="0 1 0" />
    </joint>
    <transmission name="leg1_joint2_tran">
        <type>transmission_interface/SimpleTransmission</type>
        <joint name="leg1_joint2">
            <hardwareInterface>hardware_interface/EffortJointInterface</hardwareInterface>
        </joint>
        <actuator name="leg1_joint2_motor">
            <hardwareInterface>hardware_interface/EffortJointInterface</hardwareInterface>
            <mechanicalReduction>1</mechanicalReduction>
        </actuator>
    </transmission>
    <!-- Tibia (Leg Link 2) Geometry -->
    <link name="leg1_link2">
        <inertial>
            <origin rpy="0 0 0" xyz="0 0 0" />
            <mass value="0.0012" />
            <inertia ixx="2.2899999999999997e-08" ixy="0" ixz="0" iyy="4.04e-08" iyz="0" izz="6.25e-08" />
        </inertial>
        <collision>
            <origin rpy="0 0 0" xyz="-0.011 0 0" />
            <geometry>
                <box size="0.02 0.015 0.002" />
            </geometry>
        </collision>
        <visual>
            <origin rpy="0 0 0" xyz="-0.011 0 0" />
            <geometry>
                <box size="0.02 0.015 0.002" />
            </geometry>
            <material name="Black" />
        </visual>
    </link>
    <!-- Gazebo properties -->
    <gazebo reference="leg1_link2">
        <kp>100000.0</kp>
        <kd>1.0</kd>
        <mu1>100.0</mu1>
        <mu2>100.0</mu2>
        <material>Gazebo/Black</material>
    </gazebo>
    <!-- Fixed Joint 2 -->
    <joint name="leg1_fixed_joint2" type="fixed">
        <parent link="leg1_joint_link2" />
        <child link="leg1_link2" />
        <origin rpy="0 0 0" xyz="0 0 0" />
    </joint>
    <!-- Joint Link Geometry -->
    <link name="leg1_joint_link3">
        <inertial>
            <origin rpy="0 0 0" xyz="0 0 0" />
            <mass value="9.424777960769378e-05" />
            <inertia ixx="1.7907078125461817e-09" ixy="0" ixz="0" iyy="1.7907078125461817e-09" iyz="0" izz="4.712388980384689e-11" />
        </inertial>
        <collision>
            <origin rpy="0 1.5707963267948966 0.0" xyz="0 0 0" />
            <geometry>
                <cylinder length="0.015" radius="0.001" />
            </geometry>
        </collision>
        <visual>
            <origin rpy="0 1.5707963267948966 0.0" xyz="0 0 0" />
            <geometry>
                <cylinder length="0.015" radius="0.001" />
            </geometry>
            <material name="White" />
        </visual>
    </link>
    <!-- Gazebo properties -->
    <gazebo reference="leg1_joint_link3">
        <kp>100000.0</kp>
        <kd>1.0</kd>
        <mu1>100.0</mu1>
        <mu2>100.0</mu2>
        <material>Gazebo/White</material>
    </gazebo>
    <!-- Joint 3 -->
    <joint name="leg1_joint3" type="revolute">
        <parent link="leg1_link2" />
        <child link="leg1_joint_link3" />
        <origin rpy="0 0 0" xyz="-0.013500000000000002                 0.0085 0" />
        <dynamics damping="0.0" friction="0.0" />
        <limit effort="1.0" lower="-1.5707963267948966" upper="1.5707963267948966" velocity="1.0" />
        <axis xyz="1 0 0" />
    </joint>
    <transmission name="leg1_joint3_tran">
        <type>transmission_interface/SimpleTransmission</type>
        <joint name="leg1_joint3">
            <hardwareInterface>hardware_interface/EffortJointInterface</hardwareInterface>
        </joint>
        <actuator name="leg1_joint3_motor">
            <hardwareInterface>hardware_interface/EffortJointInterface</hardwareInterface>
            <mechanicalReduction>1</mechanicalReduction>
        </actuator>
    </transmission>
    <!-- Tarsus (Leg Link 3) Geometry -->
    <link name="leg1_link3">
        <inertial>
            <origin rpy="0 0 0" xyz="0 0 0" />
            <mass value="0.0018" />
            <inertia ixx="1.3559999999999997e-07" ixy="0" ixz="0" iyy="3.434999999999999e-08" iyz="0" izz="1.6874999999999997e-07" />
        </inertial>
        <collision>
            <origin rpy="0 0 0" xyz="0 0.016 0" />
            <geometry>
                <box size="0.015 0.03 0.002" />
            </geometry>
        </collision>
        <visual>
            <origin rpy="0 0 0" xyz="0 0.016 0" />
            <geometry>
                <box size="0.015 0.03 0.002" />
            </geometry>
            <material name="Orange" />
        </visual>
    </link>
    <!-- Gazebo properties -->
    <gazebo reference="leg1_link3">
        <kp>100000.0</kp>
        <kd>1.0</kd>
        <mu1>100.0</mu1>
        <mu2>100.0</mu2>
        <material>Gazebo/Orange</material>
    </gazebo>
    <!-- Fixed Joint 3 -->
    <joint name="leg1_fixed_joint3" type="fixed">
        <parent link="leg1_joint_link3" />
        <child link="leg1_link3" />
        <origin rpy="0 0 0" xyz="0 0 0" />
    </joint>
    <!-- Joint Link Geometry -->
    <link name="leg1_joint_link4">
        <inertial>
            <origin rpy="0 0 0" xyz="0 0 0" />
            <mass value="9.424777960769378e-05" />
            <inertia ixx="1.7907078125461817e-09" ixy="0" ixz="0" iyy="1.7907078125461817e-09" iyz="0" izz="4.712388980384689e-11" />
        </inertial>
        <collision>
            <origin rpy="0 1.5707963267948966 0.0" xyz="0 0 0" />
            <geometry>
                <cylinder length="0.015" radius="0.001" />
            </geometry>
        </collision>
        <visual>
            <origin rpy="0 1.5707963267948966 0.0" xyz="0 0 0" />
            <geometry>
                <cylinder length="0.015" radius="0.001" />
            </geometry>
            <material name="White" />
        </visual>
    </link>
    <!-- Gazebo properties -->
    <gazebo reference="leg1_joint_link4">
        <kp>100000.0</kp>
        <kd>1.0</kd>
        <mu1>100.0</mu1>
        <mu2>100.0</mu2>
        <material>Gazebo/White</material>
    </gazebo>
    <!-- Fixed Joint 4 (Foot Joint) -->
    <joint name="leg1_fixed_joint4" type="fixed">
        <parent link="leg1_link3" />
        <child link="leg1_joint_link4" />
        <origin rpy="0 0 0" xyz="0 0.032 0" />
    </joint>
    <joint name="leg1_coxa_joint" type="fixed">
        <parent link="thorax" />
        <child link="leg1_coxa" />
        <origin rpy="0 0 0" xyz="0.07750000000000001 0.01 0" />
    </joint>
    <!-- Coxa Geometry -->
    <link name="leg2_coxa">
        <inertial>
            <origin rpy="0 0 0" xyz="0 0 0" />
            <mass value="0.0009" />
            <inertia ixx="1.7174999999999997e-08" ixy="0" ixz="0" iyy="1.7174999999999997e-08" iyz="0" izz="3.3749999999999995e-08" />
        </inertial>
        <collision>
            <origin rpy="0 0 0" xyz="0 0.0075 0" />
            <geometry>
                <box size="0.015 0.015 0.002" />
            </geometry>
        </collision>
        <visual>
            <origin rpy="0 0 0" xyz="0 0.0075 0" />
            <geometry>
                <box size="0.015 0.015 0.002" />
            </geometry>
            <material name="Black" />
        </visual>
    </link>
    <!-- Gazebo properties -->
    <gazebo reference="leg2_coxa">
        <kp>100000.0</kp>
        <kd>1.0</kd>
        <mu1>100.0</mu1>
        <mu2>100.0</mu2>
        <material>Gazebo/Black</material>
    </gazebo>
    <!-- Joint Link Geometry -->
    <link name="leg2_joint_link1">
        <inertial>
            <origin rpy="0 0 0" xyz="0 0 0" />
            <mass value="9.424777960769378e-05" />
            <inertia ixx="1.7907078125461817e-09" ixy="0" ixz="0" iyy="1.7907078125461817e-09" iyz="0" izz="4.712388980384689e-11" />
        </inertial>
        <collision>
            <origin rpy="0 1.5707963267948966 0.0" xyz="0 0 0" />
            <geometry>
                <cylinder length="0.015" radius="0.001" />
            </geometry>
        </collision>
        <visual>
            <origin rpy="0 1.5707963267948966 0.0" xyz="0 0 0" />
            <geometry>
                <cylinder length="0.015" radius="0.001" />
            </geometry>
            <material name="White" />
        </visual>
    </link>
    <!-- Gazebo properties -->
    <gazebo reference="leg2_joint_link1">
        <kp>100000.0</kp>
        <kd>1.0</kd>
        <mu1>100.0</mu1>
        <mu2>100.0</mu2>
        <material>Gazebo/White</material>
    </gazebo>
    <!-- Joint 1 -->
    <joint name="leg2_joint1" type="revolute">
        <parent link="leg2_coxa" />
        <child link="leg2_joint_link1" />
        <origin rpy="0 0 0" xyz="0 0.016 0" />
        <dynamics damping="0.0" friction="0.0" />
        <limit effort="1.0" lower="-1.5707963267948966" upper="1.5707963267948966" velocity="1.0" />
        <axis xyz="1 0 0" />
    </joint>
    <transmission name="leg2_joint1_tran">
        <type>transmission_interface/SimpleTransmission</type>
        <joint name="leg2_joint1">
            <hardwareInterface>hardware_interface/EffortJointInterface</hardwareInterface>
        </joint>
        <actuator name="leg2_joint1_motor">
            <hardwareInterface>hardware_interface/EffortJointInterface</hardwareInterface>
            <mechanicalReduction>1</mechanicalReduction>
        </actuator>
    </transmission>
    <!-- Femur (Leg Link 1) Geometry -->
    <link name="leg2_link1">
        <inertial>
            <origin rpy="0 0 0" xyz="0 0 0" />
            <mass value="0.0018" />
            <inertia ixx="1.3559999999999997e-07" ixy="0" ixz="0" iyy="3.434999999999999e-08" iyz="0" izz="1.6874999999999997e-07" />
        </inertial>
        <collision>
            <origin rpy="0 0 0" xyz="0 0.016 0" />
            <geometry>
                <box size="0.015 0.03 0.002" />
            </geometry>
        </collision>
        <visual>
            <origin rpy="0 0 0" xyz="0 0.016 0" />
            <geometry>
                <box size="0.015 0.03 0.002" />
            </geometry>
            <material name="Orange" />
        </visual>
    </link>
    <!-- Gazebo properties -->
    <gazebo reference="leg2_link1">
        <kp>100000.0</kp>
        <kd>1.0</kd>
        <mu1>100.0</mu1>
        <mu2>100.0</mu2>
        <material>Gazebo/Orange</material>
    </gazebo>
    <!-- Fixed Joint 1 -->
    <joint name="leg2_fixed_joint1" type="fixed">
        <parent link="leg2_joint_link1" />
        <child link="leg2_link1" />
        <origin rpy="0 0 0" xyz="0 0 0" />
    </joint>
    <!-- Joint Link Geometry -->
    <link name="leg2_joint_link2">
        <inertial>
            <origin rpy="0 0 0" xyz="0 0 0" />
            <mass value="9.424777960769378e-05" />
            <inertia ixx="1.7907078125461817e-09" ixy="0" ixz="0" iyy="1.7907078125461817e-09" iyz="0" izz="4.712388980384689e-11" />
        </inertial>
        <collision>
            <origin rpy="0 1.5707963267948966 1.5707963267948966" xyz="0 0 0" />
            <geometry>
                <cylinder length="0.015" radius="0.001" />
            </geometry>
        </collision>
        <visual>
            <origin rpy="0 1.5707963267948966 1.5707963267948966" xyz="0 0 0" />
            <geometry>
                <cylinder length="0.015" radius="0.001" />
            </geometry>
            <material name="White" />
        </visual>
    </link>
    <!-- Gazebo properties -->
    <gazebo reference="leg2_joint_link2">
        <kp>100000.0</kp>
        <kd>1.0</kd>
        <mu1>100.0</mu1>
        <mu2>100.0</mu2>
        <material>Gazebo/White</material>
    </gazebo>
    <!-- Joint 2 -->
    <joint name="leg2_joint2" type="revolute">
        <parent link="leg2_link1" />
        <child link="leg2_joint_link2" />
        <origin rpy="0 0 0" xyz="-0.0085                 0.0235 0" />
        <dynamics damping="0.0" friction="0.0" />
        <limit effort="1.0" lower="-1.5707963267948966" upper="1.5707963267948966" velocity="1.0" />
        <axis xyz="0 1 0" />
    </joint>
    <transmission name="leg2_joint2_tran">
        <type>transmission_interface/SimpleTransmission</type>
        <joint name="leg2_joint2">
            <hardwareInterface>hardware_interface/EffortJointInterface</hardwareInterface>
        </joint>
        <actuator name="leg2_joint2_motor">
            <hardwareInterface>hardware_interface/EffortJointInterface</hardwareInterface>
            <mechanicalReduction>1</mechanicalReduction>
        </actuator>
    </transmission>
    <!-- Tibia (Leg Link 2) Geometry -->
    <link name="leg2_link2">
        <inertial>
            <origin rpy="0 0 0" xyz="0 0 0" />
            <mass value="0.0012" />
            <inertia ixx="2.2899999999999997e-08" ixy="0" ixz="0" iyy="4.04e-08" iyz="0" izz="6.25e-08" />
        </inertial>
        <collision>
            <origin rpy="0 0 0" xyz="-0.011 0 0" />
            <geometry>
                <box size="0.02 0.015 0.002" />
            </geometry>
        </collision>
        <visual>
            <origin rpy="0 0 0" xyz="-0.011 0 0" />
            <geometry>
                <box size="0.02 0.015 0.002" />
            </geometry>
            <material name="Black" />
        </visual>
    </link>
    <!-- Gazebo properties -->
    <gazebo reference="leg2_link2">
        <kp>100000.0</kp>
        <kd>1.0</kd>
        <mu1>100.0</mu1>
        <mu2>100.0</mu2>
        <material>Gazebo/Black</material>
    </gazebo>
    <!-- Fixed Joint 2 -->
    <joint name="leg2_fixed_joint2" type="fixed">
        <parent link="leg2_joint_link2" />
        <child link="leg2_link2" />
        <origin rpy="0 0 0" xyz="0 0 0" />
    </joint>
    <!-- Joint Link Geometry -->
    <link name="leg2_joint_link3">
        <inertial>
            <origin rpy="0 0 0" xyz="0 0 0" />
            <mass value="9.424777960769378e-05" />
            <inertia ixx="1.7907078125461817e-09" ixy="0" ixz="0" iyy="1.7907078125461817e-09" iyz="0" izz="4.712388980384689e-11" />
        </inertial>
        <collision>
            <origin rpy="0 1.5707963267948966 0.0" xyz="0 0 0" />
            <geometry>
                <cylinder length="0.015" radius="0.001" />
            </geometry>
        </collision>
        <visual>
            <origin rpy="0 1.5707963267948966 0.0" xyz="0 0 0" />
            <geometry>
                <cylinder length="0.015" radius="0.001" />
            </geometry>
            <material name="White" />
        </visual>
    </link>
    <!-- Gazebo properties -->
    <gazebo reference="leg2_joint_link3">
        <kp>100000.0</kp>
        <kd>1.0</kd>
        <mu1>100.0</mu1>
        <mu2>100.0</mu2>
        <material>Gazebo/White</material>
    </gazebo>
    <!-- Joint 3 -->
    <joint name="leg2_joint3" type="revolute">
        <parent link="leg2_link2" />
        <child link="leg2_joint_link3" />
        <origin rpy="0 0 0" xyz="-0.013500000000000002                 0.0085 0" />
        <dynamics damping="0.0" friction="0.0" />
        <limit effort="1.0" lower="-1.5707963267948966" upper="1.5707963267948966" velocity="1.0" />
        <axis xyz="1 0 0" />
    </joint>
    <transmission name="leg2_joint3_tran">
        <type>transmission_interface/SimpleTransmission</type>
        <joint name="leg2_joint3">
            <hardwareInterface>hardware_interface/EffortJointInterface</hardwareInterface>
        </joint>
        <actuator name="leg2_joint3_motor">
            <hardwareInterface>hardware_interface/EffortJointInterface</hardwareInterface>
            <mechanicalReduction>1</mechanicalReduction>
        </actuator>
    </transmission>
    <!-- Tarsus (Leg Link 3) Geometry -->
    <link name="leg2_link3">
        <inertial>
            <origin rpy="0 0 0" xyz="0 0 0" />
            <mass value="0.0018" />
            <inertia ixx="1.3559999999999997e-07" ixy="0" ixz="0" iyy="3.434999999999999e-08" iyz="0" izz="1.6874999999999997e-07" />
        </inertial>
        <collision>
            <origin rpy="0 0 0" xyz="0 0.016 0" />
            <geometry>
                <box size="0.015 0.03 0.002" />
            </geometry>
        </collision>
        <visual>
            <origin rpy="0 0 0" xyz="0 0.016 0" />
            <geometry>
                <box size="0.015 0.03 0.002" />
            </geometry>
            <material name="Orange" />
        </visual>
    </link>
    <!-- Gazebo properties -->
    <gazebo reference="leg2_link3">
        <kp>100000.0</kp>
        <kd>1.0</kd>
        <mu1>100.0</mu1>
        <mu2>100.0</mu2>
        <material>Gazebo/Orange</material>
    </gazebo>
    <!-- Fixed Joint 3 -->
    <joint name="leg2_fixed_joint3" type="fixed">
        <parent link="leg2_joint_link3" />
        <child link="leg2_link3" />
        <origin rpy="0 0 0" xyz="0 0 0" />
    </joint>
    <!-- Joint Link Geometry -->
    <link name="leg2_joint_link4">
        <inertial>
            <origin rpy="0 0 0" xyz="0 0 0" />
            <mass value="9.424777960769378e-05" />
            <inertia ixx="1.7907078125461817e-09" ixy="0" ixz="0" iyy="1.7907078125461817e-09" iyz="0" izz="4.712388980384689e-11" />
        </inertial>
        <collision>
            <origin rpy="0 1.5707963267948966 0.0" xyz="0 0 0" />
            <geometry>
                <cylinder length="0.015" radius="0.001" />
            </geometry>
        </collision>
        <visual>
            <origin rpy="0 1.5707963267948966 0.0" xyz="0 0 0" />
            <geometry>
                <cylinder length="0.015" radius="0.001" />
            </geometry>
            <material name="White" />
        </visual>
    </link>
    <!-- Gazebo properties -->
    <gazebo reference="leg2_joint_link4">
        <kp>100000.0</kp>
        <kd>1.0</kd>
        <mu1>100.0</mu1>
        <mu2>100.0</mu2>
        <material>Gazebo/White</material>
    </gazebo>
    <!-- Fixed Joint 4 (Foot Joint) -->
    <joint name="leg2_fixed_joint4" type="fixed">
        <parent link="leg2_link3" />
        <child link="leg2_joint_link4" />
        <origin rpy="0 0 0" xyz="0 0.032 0" />
    </joint>
    <joint name="leg2_coxa_joint" type="fixed">
        <parent link="thorax" />
        <child link="leg2_coxa" />
        <origin rpy="0 0 0" xyz="0.02750000000000001 0.01 0" />
    </joint>
    <!-- Coxa Geometry -->
    <link name="leg3_coxa">
        <inertial>
            <origin rpy="0 0 0" xyz="0 0 0" />
            <mass value="0.0009" />
            <inertia ixx="1.7174999999999997e-08" ixy="0" ixz="0" iyy="1.7174999999999997e-08" iyz="0" izz="3.3749999999999995e-08" />
        </inertial>
        <collision>
            <origin rpy="0 0 0" xyz="0 0.0075 0" />
            <geometry>
                <box size="0.015 0.015 0.002" />
            </geometry>
        </collision>
        <visual>
            <origin rpy="0 0 0" xyz="0 0.0075 0" />
            <geometry>
                <box size="0.015 0.015 0.002" />
            </geometry>
            <material name="Black" />
        </visual>
    </link>
    <!-- Gazebo properties -->
    <gazebo reference="leg3_coxa">
        <kp>100000.0</kp>
        <kd>1.0</kd>
        <mu1>100.0</mu1>
        <mu2>100.0</mu2>
        <material>Gazebo/Black</material>
    </gazebo>
    <!-- Joint Link Geometry -->
    <link name="leg3_joint_link1">
        <inertial>
            <origin rpy="0 0 0" xyz="0 0 0" />
            <mass value="9.424777960769378e-05" />
            <inertia ixx="1.7907078125461817e-09" ixy="0" ixz="0" iyy="1.7907078125461817e-09" iyz="0" izz="4.712388980384689e-11" />
        </inertial>
        <collision>
            <origin rpy="0 1.5707963267948966 0.0" xyz="0 0 0" />
            <geometry>
                <cylinder length="0.015" radius="0.001" />
            </geometry>
        </collision>
        <visual>
            <origin rpy="0 1.5707963267948966 0.0" xyz="0 0 0" />
            <geometry>
                <cylinder length="0.015" radius="0.001" />
            </geometry>
            <material name="White" />
        </visual>
    </link>
    <!-- Gazebo properties -->
    <gazebo reference="leg3_joint_link1">
        <kp>100000.0</kp>
        <kd>1.0</kd>
        <mu1>100.0</mu1>
        <mu2>100.0</mu2>
        <material>Gazebo/White</material>
    </gazebo>
    <!-- Joint 1 -->
    <joint name="leg3_joint1" type="revolute">
        <parent link="leg3_coxa" />
        <child link="leg3_joint_link1" />
        <origin rpy="0 0 0" xyz="0 0.016 0" />
        <dynamics damping="0.0" friction="0.0" />
        <limit effort="1.0" lower="-1.5707963267948966" upper="1.5707963267948966" velocity="1.0" />
        <axis xyz="1 0 0" />
    </joint>
    <transmission name="leg3_joint1_tran">
        <type>transmission_interface/SimpleTransmission</type>
        <joint name="leg3_joint1">
            <hardwareInterface>hardware_interface/EffortJointInterface</hardwareInterface>
        </joint>
        <actuator name="leg3_joint1_motor">
            <hardwareInterface>hardware_interface/EffortJointInterface</hardwareInterface>
            <mechanicalReduction>1</mechanicalReduction>
        </actuator>
    </transmission>
    <!-- Femur (Leg Link 1) Geometry -->
    <link name="leg3_link1">
        <inertial>
            <origin rpy="0 0 0" xyz="0 0 0" />
            <mass value="0.0018" />
            <inertia ixx="1.3559999999999997e-07" ixy="0" ixz="0" iyy="3.434999999999999e-08" iyz="0" izz="1.6874999999999997e-07" />
        </inertial>
        <collision>
            <origin rpy="0 0 0" xyz="0 0.016 0" />
            <geometry>
                <box size="0.015 0.03 0.002" />
            </geometry>
        </collision>
        <visual>
            <origin rpy="0 0 0" xyz="0 0.016 0" />
            <geometry>
                <box size="0.015 0.03 0.002" />
            </geometry>
            <material name="Orange" />
        </visual>
    </link>
    <!-- Gazebo properties -->
    <gazebo reference="leg3_link1">
        <kp>100000.0</kp>
        <kd>1.0</kd>
        <mu1>100.0</mu1>
        <mu2>100.0</mu2>
        <material>Gazebo/Orange</material>
    </gazebo>
    <!-- Fixed Joint 1 -->
    <joint name="leg3_fixed_joint1" type="fixed">
        <parent link="leg3_joint_link1" />
        <child link="leg3_link1" />
        <origin rpy="0 0 0" xyz="0 0 0" />
    </joint>
    <!-- Joint Link Geometry -->
    <link name="leg3_joint_link2">
        <inertial>
            <origin rpy="0 0 0" xyz="0 0 0" />
            <mass value="9.424777960769378e-05" />
            <inertia ixx="1.7907078125461817e-09" ixy="0" ixz="0" iyy="1.7907078125461817e-09" iyz="0" izz="4.712388980384689e-11" />
        </inertial>
        <collision>
            <origin rpy="0 1.5707963267948966 1.5707963267948966" xyz="0 0 0" />
            <geometry>
                <cylinder length="0.015" radius="0.001" />
            </geometry>
        </collision>
        <visual>
            <origin rpy="0 1.5707963267948966 1.5707963267948966" xyz="0 0 0" />
            <geometry>
                <cylinder length="0.015" radius="0.001" />
            </geometry>
            <material name="White" />
        </visual>
    </link>
    <!-- Gazebo properties -->
    <gazebo reference="leg3_joint_link2">
        <kp>100000.0</kp>
        <kd>1.0</kd>
        <mu1>100.0</mu1>
        <mu2>100.0</mu2>
        <material>Gazebo/White</material>
    </gazebo>
    <!-- Joint 2 -->
    <joint name="leg3_joint2" type="revolute">
        <parent link="leg3_link1" />
        <child link="leg3_joint_link2" />
        <origin rpy="0 0 0" xyz="-0.0085                 0.0235 0" />
        <dynamics damping="0.0" friction="0.0" />
        <limit effort="1.0" lower="-1.5707963267948966" upper="1.5707963267948966" velocity="1.0" />
        <axis xyz="0 1 0" />
    </joint>
    <transmission name="leg3_joint2_tran">
        <type>transmission_interface/SimpleTransmission</type>
        <joint name="leg3_joint2">
            <hardwareInterface>hardware_interface/EffortJointInterface</hardwareInterface>
        </joint>
        <actuator name="leg3_joint2_motor">
            <hardwareInterface>hardware_interface/EffortJointInterface</hardwareInterface>
            <mechanicalReduction>1</mechanicalReduction>
        </actuator>
    </transmission>
    <!-- Tibia (Leg Link 2) Geometry -->
    <link name="leg3_link2">
        <inertial>
            <origin rpy="0 0 0" xyz="0 0 0" />
            <mass value="0.0012" />
            <inertia ixx="2.2899999999999997e-08" ixy="0" ixz="0" iyy="4.04e-08" iyz="0" izz="6.25e-08" />
        </inertial>
        <collision>
            <origin rpy="0 0 0" xyz="-0.011 0 0" />
            <geometry>
                <box size="0.02 0.015 0.002" />
            </geometry>
        </collision>
        <visual>
            <origin rpy="0 0 0" xyz="-0.011 0 0" />
            <geometry>
                <box size="0.02 0.015 0.002" />
            </geometry>
            <material name="Black" />
        </visual>
    </link>
    <!-- Gazebo properties -->
    <gazebo reference="leg3_link2">
        <kp>100000.0</kp>
        <kd>1.0</kd>
        <mu1>100.0</mu1>
        <mu2>100.0</mu2>
        <material>Gazebo/Black</material>
    </gazebo>
    <!-- Fixed Joint 2 -->
    <joint name="leg3_fixed_joint2" type="fixed">
        <parent link="leg3_joint_link2" />
        <child link="leg3_link2" />
        <origin rpy="0 0 0" xyz="0 0 0" />
    </joint>
    <!-- Joint Link Geometry -->
    <link name="leg3_joint_link3">
        <inertial>
            <origin rpy="0 0 0" xyz="0 0 0" />
            <mass value="9.424777960769378e-05" />
            <inertia ixx="1.7907078125461817e-09" ixy="0" ixz="0" iyy="1.7907078125461817e-09" iyz="0" izz="4.712388980384689e-11" />
        </inertial>
        <collision>
            <origin rpy="0 1.5707963267948966 0.0" xyz="0 0 0" />
            <geometry>
                <cylinder length="0.015" radius="0.001" />
            </geometry>
        </collision>
        <visual>
            <origin rpy="0 1.5707963267948966 0.0" xyz="0 0 0" />
            <geometry>
                <cylinder length="0.015" radius="0.001" />
            </geometry>
            <material name="White" />
        </visual>
    </link>
    <!-- Gazebo properties -->
    <gazebo reference="leg3_joint_link3">
        <kp>100000.0</kp>
        <kd>1.0</kd>
        <mu1>100.0</mu1>
        <mu2>100.0</mu2>
        <material>Gazebo/White</material>
    </gazebo>
    <!-- Joint 3 -->
    <joint name="leg3_joint3" type="revolute">
        <parent link="leg3_link2" />
        <child link="leg3_joint_link3" />
        <origin rpy="0 0 0" xyz="-0.013500000000000002                 0.0085 0" />
        <dynamics damping="0.0" friction="0.0" />
        <limit effort="1.0" lower="-1.5707963267948966" upper="1.5707963267948966" velocity="1.0" />
        <axis xyz="1 0 0" />
    </joint>
    <transmission name="leg3_joint3_tran">
        <type>transmission_interface/SimpleTransmission</type>
        <joint name="leg3_joint3">
            <hardwareInterface>hardware_interface/EffortJointInterface</hardwareInterface>
        </joint>
        <actuator name="leg3_joint3_motor">
            <hardwareInterface>hardware_interface/EffortJointInterface</hardwareInterface>
            <mechanicalReduction>1</mechanicalReduction>
        </actuator>
    </transmission>
    <!-- Tarsus (Leg Link 3) Geometry -->
    <link name="leg3_link3">
        <inertial>
            <origin rpy="0 0 0" xyz="0 0 0" />
            <mass value="0.0018" />
            <inertia ixx="1.3559999999999997e-07" ixy="0" ixz="0" iyy="3.434999999999999e-08" iyz="0" izz="1.6874999999999997e-07" />
        </inertial>
        <collision>
            <origin rpy="0 0 0" xyz="0 0.016 0" />
            <geometry>
                <box size="0.015 0.03 0.002" />
            </geometry>
        </collision>
        <visual>
            <origin rpy="0 0 0" xyz="0 0.016 0" />
            <geometry>
                <box size="0.015 0.03 0.002" />
            </geometry>
            <material name="Orange" />
        </visual>
    </link>
    <!-- Gazebo properties -->
    <gazebo reference="leg3_link3">
        <kp>100000.0</kp>
        <kd>1.0</kd>
        <mu1>100.0</mu1>
        <mu2>100.0</mu2>
        <material>Gazebo/Orange</material>
    </gazebo>
    <!-- Fixed Joint 3 -->
    <joint name="leg3_fixed_joint3" type="fixed">
        <parent link="leg3_joint_link3" />
        <child link="leg3_link3" />
        <origin rpy="0 0 0" xyz="0 0 0" />
    </joint>
    <!-- Joint Link Geometry -->
    <link name="leg3_joint_link4">
        <inertial>
            <origin rpy="0 0 0" xyz="0 0 0" />
            <mass value="9.424777960769378e-05" />
            <inertia ixx="1.7907078125461817e-09" ixy="0" ixz="0" iyy="1.7907078125461817e-09" iyz="0" izz="4.712388980384689e-11" />
        </inertial>
        <collision>
            <origin rpy="0 1.5707963267948966 0.0" xyz="0 0 0" />
            <geometry>
                <cylinder length="0.015" radius="0.001" />
            </geometry>
        </collision>
        <visual>
            <origin rpy="0 1.5707963267948966 0.0" xyz="0 0 0" />
            <geometry>
                <cylinder length="0.015" radius="0.001" />
            </geometry>
            <material name="White" />
        </visual>
    </link>
    <!-- Gazebo properties -->
    <gazebo reference="leg3_joint_link4">
        <kp>100000.0</kp>
        <kd>1.0</kd>
        <mu1>100.0</mu1>
        <mu2>100.0</mu2>
        <material>Gazebo/White</material>
    </gazebo>
    <!-- Fixed Joint 4 (Foot Joint) -->
    <joint name="leg3_fixed_joint4" type="fixed">
        <parent link="leg3_link3" />
        <child link="leg3_joint_link4" />
        <origin rpy="0 0 0" xyz="0 0.032 0" />
    </joint>
    <joint name="leg3_coxa_joint" type="fixed">
        <parent link="thorax" />
        <child link="leg3_coxa" />
        <origin rpy="0 0 0" xyz="-0.022499999999999992 0.01 0" />
    </joint>
    <!-- Coxa Geometry -->
    <link name="leg4_coxa">
        <inertial>
            <origin rpy="0 0 0" xyz="0 0 0" />
            <mass value="0.0009" />
            <inertia ixx="1.7174999999999997e-08" ixy="0" ixz="0" iyy="1.7174999999999997e-08" iyz="0" izz="3.3749999999999995e-08" />
        </inertial>
        <collision>
            <origin rpy="0 0 0" xyz="0 0.0075 0" />
            <geometry>
                <box size="0.015 0.015 0.002" />
            </geometry>
        </collision>
        <visual>
            <origin rpy="0 0 0" xyz="0 0.0075 0" />
            <geometry>
                <box size="0.015 0.015 0.002" />
            </geometry>
            <material name="Black" />
        </visual>
    </link>
    <!-- Gazebo properties -->
    <gazebo reference="leg4_coxa">
        <kp>100000.0</kp>
        <kd>1.0</kd>
        <mu1>100.0</mu1>
        <mu2>100.0</mu2>
        <material>Gazebo/Black</material>
    </gazebo>
    <!-- Joint Link Geometry -->
    <link name="leg4_joint_link1">
        <inertial>
            <origin rpy="0 0 0" xyz="0 0 0" />
            <mass value="9.424777960769378e-05" />
            <inertia ixx="1.7907078125461817e-09" ixy="0" ixz="0" iyy="1.7907078125461817e-09" iyz="0" izz="4.712388980384689e-11" />
        </inertial>
        <collision>
            <origin rpy="0 1.5707963267948966 0.0" xyz="0 0 0" />
            <geometry>
                <cylinder length="0.015" radius="0.001" />
            </geometry>
        </collision>
        <visual>
            <origin rpy="0 1.5707963267948966 0.0" xyz="0 0 0" />
            <geometry>
                <cylinder length="0.015" radius="0.001" />
            </geometry>
            <material name="White" />
        </visual>
    </link>
    <!-- Gazebo properties -->
    <gazebo reference="leg4_joint_link1">
        <kp>100000.0</kp>
        <kd>1.0</kd>
        <mu1>100.0</mu1>
        <mu2>100.0</mu2>
        <material>Gazebo/White</material>
    </gazebo>
    <!-- Joint 1 -->
    <joint name="leg4_joint1" type="revolute">
        <parent link="leg4_coxa" />
        <child link="leg4_joint_link1" />
        <origin rpy="0 0 0" xyz="0 0.016 0" />
        <dynamics damping="0.0" friction="0.0" />
        <limit effort="1.0" lower="-1.5707963267948966" upper="1.5707963267948966" velocity="1.0" />
        <axis xyz="1 0 0" />
    </joint>
    <transmission name="leg4_joint1_tran">
        <type>transmission_interface/SimpleTransmission</type>
        <joint name="leg4_joint1">
            <hardwareInterface>hardware_interface/EffortJointInterface</hardwareInterface>
        </joint>
        <actuator name="leg4_joint1_motor">
            <hardwareInterface>hardware_interface/EffortJointInterface</hardwareInterface>
            <mechanicalReduction>1</mechanicalReduction>
        </actuator>
    </transmission>
    <!-- Femur (Leg Link 1) Geometry -->
    <link name="leg4_link1">
        <inertial>
            <origin rpy="0 0 0" xyz="0 0 0" />
            <mass value="0.0018" />
            <inertia ixx="1.3559999999999997e-07" ixy="0" ixz="0" iyy="3.434999999999999e-08" iyz="0" izz="1.6874999999999997e-07" />
        </inertial>
        <collision>
            <origin rpy="0 0 0" xyz="0 0.016 0" />
            <geometry>
                <box size="0.015 0.03 0.002" />
            </geometry>
        </collision>
        <visual>
            <origin rpy="0 0 0" xyz="0 0.016 0" />
            <geometry>
                <box size="0.015 0.03 0.002" />
            </geometry>
            <material name="Orange" />
        </visual>
    </link>
    <!-- Gazebo properties -->
    <gazebo reference="leg4_link1">
        <kp>100000.0</kp>
        <kd>1.0</kd>
        <mu1>100.0</mu1>
        <mu2>100.0</mu2>
        <material>Gazebo/Orange</material>
    </gazebo>
    <!-- Fixed Joint 1 -->
    <joint name="leg4_fixed_joint1" type="fixed">
        <parent link="leg4_joint_link1" />
        <child link="leg4_link1" />
        <origin rpy="0 0 0" xyz="0 0 0" />
    </joint>
    <!-- Joint Link Geometry -->
    <link name="leg4_joint_link2">
        <inertial>
            <origin rpy="0 0 0" xyz="0 0 0" />
            <mass value="9.424777960769378e-05" />
            <inertia ixx="1.7907078125461817e-09" ixy="0" ixz="0" iyy="1.7907078125461817e-09" iyz="0" izz="4.712388980384689e-11" />
        </inertial>
        <collision>
            <origin rpy="0 1.5707963267948966 1.5707963267948966" xyz="0 0 0" />
            <geometry>
                <cylinder length="0.015" radius="0.001" />
            </geometry>
        </collision>
        <visual>
            <origin rpy="0 1.5707963267948966 1.5707963267948966" xyz="0 0 0" />
            <geometry>
                <cylinder length="0.015" radius="0.001" />
            </geometry>
            <material name="White" />
        </visual>
    </link>
    <!-- Gazebo properties -->
    <gazebo reference="leg4_joint_link2">
        <kp>100000.0</kp>
        <kd>1.0</kd>
        <mu1>100.0</mu1>
        <mu2>100.0</mu2>
        <material>Gazebo/White</material>
    </gazebo>
    <!-- Joint 2 -->
    <joint name="leg4_joint2" type="revolute">
        <parent link="leg4_link1" />
        <child link="leg4_joint_link2" />
        <origin rpy="0 0 0" xyz="-0.0085                 0.0235 0" />
        <dynamics damping="0.0" friction="0.0" />
        <limit effort="1.0" lower="-1.5707963267948966" upper="1.5707963267948966" velocity="1.0" />
        <axis xyz="0 1 0" />
    </joint>
    <transmission name="leg4_joint2_tran">
        <type>transmission_interface/SimpleTransmission</type>
        <joint name="leg4_joint2">
            <hardwareInterface>hardware_interface/EffortJointInterface</hardwareInterface>
        </joint>
        <actuator name="leg4_joint2_motor">
            <hardwareInterface>hardware_interface/EffortJointInterface</hardwareInterface>
            <mechanicalReduction>1</mechanicalReduction>
        </actuator>
    </transmission>
    <!-- Tibia (Leg Link 2) Geometry -->
    <link name="leg4_link2">
        <inertial>
            <origin rpy="0 0 0" xyz="0 0 0" />
            <mass value="0.0012" />
            <inertia ixx="2.2899999999999997e-08" ixy="0" ixz="0" iyy="4.04e-08" iyz="0" izz="6.25e-08" />
        </inertial>
        <collision>
            <origin rpy="0 0 0" xyz="-0.011 0 0" />
            <geometry>
                <box size="0.02 0.015 0.002" />
            </geometry>
        </collision>
        <visual>
            <origin rpy="0 0 0" xyz="-0.011 0 0" />
            <geometry>
                <box size="0.02 0.015 0.002" />
            </geometry>
            <material name="Black" />
        </visual>
    </link>
    <!-- Gazebo properties -->
    <gazebo reference="leg4_link2">
        <kp>100000.0</kp>
        <kd>1.0</kd>
        <mu1>100.0</mu1>
        <mu2>100.0</mu2>
        <material>Gazebo/Black</material>
    </gazebo>
    <!-- Fixed Joint 2 -->
    <joint name="leg4_fixed_joint2" type="fixed">
        <parent link="leg4_joint_link2" />
        <child link="leg4_link2" />
        <origin rpy="0 0 0" xyz="0 0 0" />
    </joint>
    <!-- Joint Link Geometry -->
    <link name="leg4_joint_link3">
        <inertial>
            <origin rpy="0 0 0" xyz="0 0 0" />
            <mass value="9.424777960769378e-05" />
            <inertia ixx="1.7907078125461817e-09" ixy="0" ixz="0" iyy="1.7907078125461817e-09" iyz="0" izz="4.712388980384689e-11" />
        </inertial>
        <collision>
            <origin rpy="0 1.5707963267948966 0.0" xyz="0 0 0" />
            <geometry>
                <cylinder length="0.015" radius="0.001" />
            </geometry>
        </collision>
        <visual>
            <origin rpy="0 1.5707963267948966 0.0" xyz="0 0 0" />
            <geometry>
                <cylinder length="0.015" radius="0.001" />
            </geometry>
            <material name="White" />
        </visual>
    </link>
    <!-- Gazebo properties -->
    <gazebo reference="leg4_joint_link3">
        <kp>100000.0</kp>
        <kd>1.0</kd>
        <mu1>100.0</mu1>
        <mu2>100.0</mu2>
        <material>Gazebo/White</material>
    </gazebo>
    <!-- Joint 3 -->
    <joint name="leg4_joint3" type="revolute">
        <parent link="leg4_link2" />
        <child link="leg4_joint_link3" />
        <origin rpy="0 0 0" xyz="-0.013500000000000002                 0.0085 0" />
        <dynamics damping="0.0" friction="0.0" />
        <limit effort="1.0" lower="-1.5707963267948966" upper="1.5707963267948966" velocity="1.0" />
        <axis xyz="1 0 0" />
    </joint>
    <transmission name="leg4_joint3_tran">
        <type>transmission_interface/SimpleTransmission</type>
        <joint name="leg4_joint3">
            <hardwareInterface>hardware_interface/EffortJointInterface</hardwareInterface>
        </joint>
        <actuator name="leg4_joint3_motor">
            <hardwareInterface>hardware_interface/EffortJointInterface</hardwareInterface>
            <mechanicalReduction>1</mechanicalReduction>
        </actuator>
    </transmission>
    <!-- Tarsus (Leg Link 3) Geometry -->
    <link name="leg4_link3">
        <inertial>
            <origin rpy="0 0 0" xyz="0 0 0" />
            <mass value="0.0018" />
            <inertia ixx="1.3559999999999997e-07" ixy="0" ixz="0" iyy="3.434999999999999e-08" iyz="0" izz="1.6874999999999997e-07" />
        </inertial>
        <collision>
            <origin rpy="0 0 0" xyz="0 0.016 0" />
            <geometry>
                <box size="0.015 0.03 0.002" />
            </geometry>
        </collision>
        <visual>
            <origin rpy="0 0 0" xyz="0 0.016 0" />
            <geometry>
                <box size="0.015 0.03 0.002" />
            </geometry>
            <material name="Orange" />
        </visual>
    </link>
    <!-- Gazebo properties -->
    <gazebo reference="leg4_link3">
        <kp>100000.0</kp>
        <kd>1.0</kd>
        <mu1>100.0</mu1>
        <mu2>100.0</mu2>
        <material>Gazebo/Orange</material>
    </gazebo>
    <!-- Fixed Joint 3 -->
    <joint name="leg4_fixed_joint3" type="fixed">
        <parent link="leg4_joint_link3" />
        <child link="leg4_link3" />
        <origin rpy="0 0 0" xyz="0 0 0" />
    </joint>
    <!-- Joint Link Geometry -->
    <link name="leg4_joint_link4">
        <inertial>
            <origin rpy="0 0 0" xyz="0 0 0" />
            <mass value="9.424777960769378e-05" />
            <inertia ixx="1.7907078125461817e-09" ixy="0" ixz="0" iyy="1.7907078125461817e-09" iyz="0" izz="4.712388980384689e-11" />
        </inertial>
        <collision>
            <origin rpy="0 1.5707963267948966 0.0" xyz="0 0 0" />
            <geometry>
                <cylinder length="0.015" radius="0.001" />
            </geometry>
        </collision>
        <visual>
            <origin rpy="0 1.5707963267948966 0.0" xyz="0 0 0" />
            <geometry>
                <cylinder length="0.015" radius="0.001" />
            </geometry>
            <material name="White" />
        </visual>
    </link>
    <!-- Gazebo properties -->
    <gazebo reference="leg4_joint_link4">
        <kp>100000.0</kp>
        <kd>1.0</kd>
        <mu1>100.0</mu1>
        <mu2>100.0</mu2>
        <material>Gazebo/White</material>
    </gazebo>
    <!-- Fixed Joint 4 (Foot Joint) -->
    <joint name="leg4_fixed_joint4" type="fixed">
        <parent link="leg4_link3" />
        <child link="leg4_joint_link4" />
        <origin rpy="0 0 0" xyz="0 0.032 0" />
    </joint>
    <joint name="leg4_coxa_joint" type="fixed">
        <parent link="thorax" />
        <child link="leg4_coxa" />
        <origin rpy="3.141592653589793 0 0" xyz="0.07750000000000001 -0.01 0" />
    </joint>
    <!-- Coxa Geometry -->
    <link name="leg5_coxa">
        <inertial>
            <origin rpy="0 0 0" xyz="0 0 0" />
            <mass value="0.0009" />
            <inertia ixx="1.7174999999999997e-08" ixy="0" ixz="0" iyy="1.7174999999999997e-08" iyz="0" izz="3.3749999999999995e-08" />
        </inertial>
        <collision>
            <origin rpy="0 0 0" xyz="0 0.0075 0" />
            <geometry>
                <box size="0.015 0.015 0.002" />
            </geometry>
        </collision>
        <visual>
            <origin rpy="0 0 0" xyz="0 0.0075 0" />
            <geometry>
                <box size="0.015 0.015 0.002" />
            </geometry>
            <material name="Black" />
        </visual>
    </link>
    <!-- Gazebo properties -->
    <gazebo reference="leg5_coxa">
        <kp>100000.0</kp>
        <kd>1.0</kd>
        <mu1>100.0</mu1>
        <mu2>100.0</mu2>
        <material>Gazebo/Black</material>
    </gazebo>
    <!-- Joint Link Geometry -->
    <link name="leg5_joint_link1">
        <inertial>
            <origin rpy="0 0 0" xyz="0 0 0" />
            <mass value="9.424777960769378e-05" />
            <inertia ixx="1.7907078125461817e-09" ixy="0" ixz="0" iyy="1.7907078125461817e-09" iyz="0" izz="4.712388980384689e-11" />
        </inertial>
        <collision>
            <origin rpy="0 1.5707963267948966 0.0" xyz="0 0 0" />
            <geometry>
                <cylinder length="0.015" radius="0.001" />
            </geometry>
        </collision>
        <visual>
            <origin rpy="0 1.5707963267948966 0.0" xyz="0 0 0" />
            <geometry>
                <cylinder length="0.015" radius="0.001" />
            </geometry>
            <material name="White" />
        </visual>
    </link>
    <!-- Gazebo properties -->
    <gazebo reference="leg5_joint_link1">
        <kp>100000.0</kp>
        <kd>1.0</kd>
        <mu1>100.0</mu1>
        <mu2>100.0</mu2>
        <material>Gazebo/White</material>
    </gazebo>
    <!-- Joint 1 -->
    <joint name="leg5_joint1" type="revolute">
        <parent link="leg5_coxa" />
        <child link="leg5_joint_link1" />
        <origin rpy="0 0 0" xyz="0 0.016 0" />
        <dynamics damping="0.0" friction="0.0" />
        <limit effort="1.0" lower="-1.5707963267948966" upper="1.5707963267948966" velocity="1.0" />
        <axis xyz="1 0 0" />
    </joint>
    <transmission name="leg5_joint1_tran">
        <type>transmission_interface/SimpleTransmission</type>
        <joint name="leg5_joint1">
            <hardwareInterface>hardware_interface/EffortJointInterface</hardwareInterface>
        </joint>
        <actuator name="leg5_joint1_motor">
            <hardwareInterface>hardware_interface/EffortJointInterface</hardwareInterface>
            <mechanicalReduction>1</mechanicalReduction>
        </actuator>
    </transmission>
    <!-- Femur (Leg Link 1) Geometry -->
    <link name="leg5_link1">
        <inertial>
            <origin rpy="0 0 0" xyz="0 0 0" />
            <mass value="0.0018" />
            <inertia ixx="1.3559999999999997e-07" ixy="0" ixz="0" iyy="3.434999999999999e-08" iyz="0" izz="1.6874999999999997e-07" />
        </inertial>
        <collision>
            <origin rpy="0 0 0" xyz="0 0.016 0" />
            <geometry>
                <box size="0.015 0.03 0.002" />
            </geometry>
        </collision>
        <visual>
            <origin rpy="0 0 0" xyz="0 0.016 0" />
            <geometry>
                <box size="0.015 0.03 0.002" />
            </geometry>
            <material name="Orange" />
        </visual>
    </link>
    <!-- Gazebo properties -->
    <gazebo reference="leg5_link1">
        <kp>100000.0</kp>
        <kd>1.0</kd>
        <mu1>100.0</mu1>
        <mu2>100.0</mu2>
        <material>Gazebo/Orange</material>
    </gazebo>
    <!-- Fixed Joint 1 -->
    <joint name="leg5_fixed_joint1" type="fixed">
        <parent link="leg5_joint_link1" />
        <child link="leg5_link1" />
        <origin rpy="0 0 0" xyz="0 0 0" />
    </joint>
    <!-- Joint Link Geometry -->
    <link name="leg5_joint_link2">
        <inertial>
            <origin rpy="0 0 0" xyz="0 0 0" />
            <mass value="9.424777960769378e-05" />
            <inertia ixx="1.7907078125461817e-09" ixy="0" ixz="0" iyy="1.7907078125461817e-09" iyz="0" izz="4.712388980384689e-11" />
        </inertial>
        <collision>
            <origin rpy="0 1.5707963267948966 1.5707963267948966" xyz="0 0 0" />
            <geometry>
                <cylinder length="0.015" radius="0.001" />
            </geometry>
        </collision>
        <visual>
            <origin rpy="0 1.5707963267948966 1.5707963267948966" xyz="0 0 0" />
            <geometry>
                <cylinder length="0.015" radius="0.001" />
            </geometry>
            <material name="White" />
        </visual>
    </link>
    <!-- Gazebo properties -->
    <gazebo reference="leg5_joint_link2">
        <kp>100000.0</kp>
        <kd>1.0</kd>
        <mu1>100.0</mu1>
        <mu2>100.0</mu2>
        <material>Gazebo/White</material>
    </gazebo>
    <!-- Joint 2 -->
    <joint name="leg5_joint2" type="revolute">
        <parent link="leg5_link1" />
        <child link="leg5_joint_link2" />
        <origin rpy="0 0 0" xyz="-0.0085                 0.0235 0" />
        <dynamics damping="0.0" friction="0.0" />
        <limit effort="1.0" lower="-1.5707963267948966" upper="1.5707963267948966" velocity="1.0" />
        <axis xyz="0 1 0" />
    </joint>
    <transmission name="leg5_joint2_tran">
        <type>transmission_interface/SimpleTransmission</type>
        <joint name="leg5_joint2">
            <hardwareInterface>hardware_interface/EffortJointInterface</hardwareInterface>
        </joint>
        <actuator name="leg5_joint2_motor">
            <hardwareInterface>hardware_interface/EffortJointInterface</hardwareInterface>
            <mechanicalReduction>1</mechanicalReduction>
        </actuator>
    </transmission>
    <!-- Tibia (Leg Link 2) Geometry -->
    <link name="leg5_link2">
        <inertial>
            <origin rpy="0 0 0" xyz="0 0 0" />
            <mass value="0.0012" />
            <inertia ixx="2.2899999999999997e-08" ixy="0" ixz="0" iyy="4.04e-08" iyz="0" izz="6.25e-08" />
        </inertial>
        <collision>
            <origin rpy="0 0 0" xyz="-0.011 0 0" />
            <geometry>
                <box size="0.02 0.015 0.002" />
            </geometry>
        </collision>
        <visual>
            <origin rpy="0 0 0" xyz="-0.011 0 0" />
            <geometry>
                <box size="0.02 0.015 0.002" />
            </geometry>
            <material name="Black" />
        </visual>
    </link>
    <!-- Gazebo properties -->
    <gazebo reference="leg5_link2">
        <kp>100000.0</kp>
        <kd>1.0</kd>
        <mu1>100.0</mu1>
        <mu2>100.0</mu2>
        <material>Gazebo/Black</material>
    </gazebo>
    <!-- Fixed Joint 2 -->
    <joint name="leg5_fixed_joint2" type="fixed">
        <parent link="leg5_joint_link2" />
        <child link="leg5_link2" />
        <origin rpy="0 0 0" xyz="0 0 0" />
    </joint>
    <!-- Joint Link Geometry -->
    <link name="leg5_joint_link3">
        <inertial>
            <origin rpy="0 0 0" xyz="0 0 0" />
            <mass value="9.424777960769378e-05" />
            <inertia ixx="1.7907078125461817e-09" ixy="0" ixz="0" iyy="1.7907078125461817e-09" iyz="0" izz="4.712388980384689e-11" />
        </inertial>
        <collision>
            <origin rpy="0 1.5707963267948966 0.0" xyz="0 0 0" />
            <geometry>
                <cylinder length="0.015" radius="0.001" />
            </geometry>
        </collision>
        <visual>
            <origin rpy="0 1.5707963267948966 0.0" xyz="0 0 0" />
            <geometry>
                <cylinder length="0.015" radius="0.001" />
            </geometry>
            <material name="White" />
        </visual>
    </link>
    <!-- Gazebo properties -->
    <gazebo reference="leg5_joint_link3">
        <kp>100000.0</kp>
        <kd>1.0</kd>
        <mu1>100.0</mu1>
        <mu2>100.0</mu2>
        <material>Gazebo/White</material>
    </gazebo>
    <!-- Joint 3 -->
    <joint name="leg5_joint3" type="revolute">
        <parent link="leg5_link2" />
        <child link="leg5_joint_link3" />
        <origin rpy="0 0 0" xyz="-0.013500000000000002                 0.0085 0" />
        <dynamics damping="0.0" friction="0.0" />
        <limit effort="1.0" lower="-1.5707963267948966" upper="1.5707963267948966" velocity="1.0" />
        <axis xyz="1 0 0" />
    </joint>
    <transmission name="leg5_joint3_tran">
        <type>transmission_interface/SimpleTransmission</type>
        <joint name="leg5_joint3">
            <hardwareInterface>hardware_interface/EffortJointInterface</hardwareInterface>
        </joint>
        <actuator name="leg5_joint3_motor">
            <hardwareInterface>hardware_interface/EffortJointInterface</hardwareInterface>
            <mechanicalReduction>1</mechanicalReduction>
        </actuator>
    </transmission>
    <!-- Tarsus (Leg Link 3) Geometry -->
    <link name="leg5_link3">
        <inertial>
            <origin rpy="0 0 0" xyz="0 0 0" />
            <mass value="0.0018" />
            <inertia ixx="1.3559999999999997e-07" ixy="0" ixz="0" iyy="3.434999999999999e-08" iyz="0" izz="1.6874999999999997e-07" />
        </inertial>
        <collision>
            <origin rpy="0 0 0" xyz="0 0.016 0" />
            <geometry>
                <box size="0.015 0.03 0.002" />
            </geometry>
        </collision>
        <visual>
            <origin rpy="0 0 0" xyz="0 0.016 0" />
            <geometry>
                <box size="0.015 0.03 0.002" />
            </geometry>
            <material name="Orange" />
        </visual>
    </link>
    <!-- Gazebo properties -->
    <gazebo reference="leg5_link3">
        <kp>100000.0</kp>
        <kd>1.0</kd>
        <mu1>100.0</mu1>
        <mu2>100.0</mu2>
        <material>Gazebo/Orange</material>
    </gazebo>
    <!-- Fixed Joint 3 -->
    <joint name="leg5_fixed_joint3" type="fixed">
        <parent link="leg5_joint_link3" />
        <child link="leg5_link3" />
        <origin rpy="0 0 0" xyz="0 0 0" />
    </joint>
    <!-- Joint Link Geometry -->
    <link name="leg5_joint_link4">
        <inertial>
            <origin rpy="0 0 0" xyz="0 0 0" />
            <mass value="9.424777960769378e-05" />
            <inertia ixx="1.7907078125461817e-09" ixy="0" ixz="0" iyy="1.7907078125461817e-09" iyz="0" izz="4.712388980384689e-11" />
        </inertial>
        <collision>
            <origin rpy="0 1.5707963267948966 0.0" xyz="0 0 0" />
            <geometry>
                <cylinder length="0.015" radius="0.001" />
            </geometry>
        </collision>
        <visual>
            <origin rpy="0 1.5707963267948966 0.0" xyz="0 0 0" />
            <geometry>
                <cylinder length="0.015" radius="0.001" />
            </geometry>
            <material name="White" />
        </visual>
    </link>
    <!-- Gazebo properties -->
    <gazebo reference="leg5_joint_link4">
        <kp>100000.0</kp>
        <kd>1.0</kd>
        <mu1>100.0</mu1>
        <mu2>100.0</mu2>
        <material>Gazebo/White</material>
    </gazebo>
    <!-- Fixed Joint 4 (Foot Joint) -->
    <joint name="leg5_fixed_joint4" type="fixed">
        <parent link="leg5_link3" />
        <child link="leg5_joint_link4" />
        <origin rpy="0 0 0" xyz="0 0.032 0" />
    </joint>
    <joint name="leg5_coxa_joint" type="fixed">
        <parent link="thorax" />
        <child link="leg5_coxa" />
        <origin rpy="3.141592653589793 0 0" xyz="0.02750000000000001 -0.01 0" />
    </joint>
    <!-- Coxa Geometry -->
    <link name="leg6_coxa">
        <inertial>
            <origin rpy="0 0 0" xyz="0 0 0" />
            <mass value="0.0009" />
            <inertia ixx="1.7174999999999997e-08" ixy="0" ixz="0" iyy="1.7174999999999997e-08" iyz="0" izz="3.3749999999999995e-08" />
        </inertial>
        <collision>
            <origin rpy="0 0 0" xyz="0 0.0075 0" />
            <geometry>
                <box size="0.015 0.015 0.002" />
            </geometry>
        </collision>
        <visual>
            <origin rpy="0 0 0" xyz="0 0.0075 0" />
            <geometry>
                <box size="0.015 0.015 0.002" />
            </geometry>
            <material name="Black" />
        </visual>
    </link>
    <!-- Gazebo properties -->
    <gazebo reference="leg6_coxa">
        <kp>100000.0</kp>
        <kd>1.0</kd>
        <mu1>100.0</mu1>
        <mu2>100.0</mu2>
        <material>Gazebo/Black</material>
    </gazebo>
    <!-- Joint Link Geometry -->
    <link name="leg6_joint_link1">
        <inertial>
            <origin rpy="0 0 0" xyz="0 0 0" />
            <mass value="9.424777960769378e-05" />
            <inertia ixx="1.7907078125461817e-09" ixy="0" ixz="0" iyy="1.7907078125461817e-09" iyz="0" izz="4.712388980384689e-11" />
        </inertial>
        <collision>
            <origin rpy="0 1.5707963267948966 0.0" xyz="0 0 0" />
            <geometry>
                <cylinder length="0.015" radius="0.001" />
            </geometry>
        </collision>
        <visual>
            <origin rpy="0 1.5707963267948966 0.0" xyz="0 0 0" />
            <geometry>
                <cylinder length="0.015" radius="0.001" />
            </geometry>
            <material name="White" />
        </visual>
    </link>
    <!-- Gazebo properties -->
    <gazebo reference="leg6_joint_link1">
        <kp>100000.0</kp>
        <kd>1.0</kd>
        <mu1>100.0</mu1>
        <mu2>100.0</mu2>
        <material>Gazebo/White</material>
    </gazebo>
    <!-- Joint 1 -->
    <joint name="leg6_joint1" type="revolute">
        <parent link="leg6_coxa" />
        <child link="leg6_joint_link1" />
        <origin rpy="0 0 0" xyz="0 0.016 0" />
        <dynamics damping="0.0" friction="0.0" />
        <limit effort="1.0" lower="-1.5707963267948966" upper="1.5707963267948966" velocity="1.0" />
        <axis xyz="1 0 0" />
    </joint>
    <transmission name="leg6_joint1_tran">
        <type>transmission_interface/SimpleTransmission</type>
        <joint name="leg6_joint1">
            <hardwareInterface>hardware_interface/EffortJointInterface</hardwareInterface>
        </joint>
        <actuator name="leg6_joint1_motor">
            <hardwareInterface>hardware_interface/EffortJointInterface</hardwareInterface>
            <mechanicalReduction>1</mechanicalReduction>
        </actuator>
    </transmission>
    <!-- Femur (Leg Link 1) Geometry -->
    <link name="leg6_link1">
        <inertial>
            <origin rpy="0 0 0" xyz="0 0 0" />
            <mass value="0.0018" />
            <inertia ixx="1.3559999999999997e-07" ixy="0" ixz="0" iyy="3.434999999999999e-08" iyz="0" izz="1.6874999999999997e-07" />
        </inertial>
        <collision>
            <origin rpy="0 0 0" xyz="0 0.016 0" />
            <geometry>
                <box size="0.015 0.03 0.002" />
            </geometry>
        </collision>
        <visual>
            <origin rpy="0 0 0" xyz="0 0.016 0" />
            <geometry>
                <box size="0.015 0.03 0.002" />
            </geometry>
            <material name="Orange" />
        </visual>
    </link>
    <!-- Gazebo properties -->
    <gazebo reference="leg6_link1">
        <kp>100000.0</kp>
        <kd>1.0</kd>
        <mu1>100.0</mu1>
        <mu2>100.0</mu2>
        <material>Gazebo/Orange</material>
    </gazebo>
    <!-- Fixed Joint 1 -->
    <joint name="leg6_fixed_joint1" type="fixed">
        <parent link="leg6_joint_link1" />
        <child link="leg6_link1" />
        <origin rpy="0 0 0" xyz="0 0 0" />
    </joint>
    <!-- Joint Link Geometry -->
    <link name="leg6_joint_link2">
        <inertial>
            <origin rpy="0 0 0" xyz="0 0 0" />
            <mass value="9.424777960769378e-05" />
            <inertia ixx="1.7907078125461817e-09" ixy="0" ixz="0" iyy="1.7907078125461817e-09" iyz="0" izz="4.712388980384689e-11" />
        </inertial>
        <collision>
            <origin rpy="0 1.5707963267948966 1.5707963267948966" xyz="0 0 0" />
            <geometry>
                <cylinder length="0.015" radius="0.001" />
            </geometry>
        </collision>
        <visual>
            <origin rpy="0 1.5707963267948966 1.5707963267948966" xyz="0 0 0" />
            <geometry>
                <cylinder length="0.015" radius="0.001" />
            </geometry>
            <material name="White" />
        </visual>
    </link>
    <!-- Gazebo properties -->
    <gazebo reference="leg6_joint_link2">
        <kp>100000.0</kp>
        <kd>1.0</kd>
        <mu1>100.0</mu1>
        <mu2>100.0</mu2>
        <material>Gazebo/White</material>
    </gazebo>
    <!-- Joint 2 -->
    <joint name="leg6_joint2" type="revolute">
        <parent link="leg6_link1" />
        <child link="leg6_joint_link2" />
        <origin rpy="0 0 0" xyz="-0.0085                 0.0235 0" />
        <dynamics damping="0.0" friction="0.0" />
        <limit effort="1.0" lower="-1.5707963267948966" upper="1.5707963267948966" velocity="1.0" />
        <axis xyz="0 1 0" />
    </joint>
    <transmission name="leg6_joint2_tran">
        <type>transmission_interface/SimpleTransmission</type>
        <joint name="leg6_joint2">
            <hardwareInterface>hardware_interface/EffortJointInterface</hardwareInterface>
        </joint>
        <actuator name="leg6_joint2_motor">
            <hardwareInterface>hardware_interface/EffortJointInterface</hardwareInterface>
            <mechanicalReduction>1</mechanicalReduction>
        </actuator>
    </transmission>
    <!-- Tibia (Leg Link 2) Geometry -->
    <link name="leg6_link2">
        <inertial>
            <origin rpy="0 0 0" xyz="0 0 0" />
            <mass value="0.0012" />
            <inertia ixx="2.2899999999999997e-08" ixy="0" ixz="0" iyy="4.04e-08" iyz="0" izz="6.25e-08" />
        </inertial>
        <collision>
            <origin rpy="0 0 0" xyz="-0.011 0 0" />
            <geometry>
                <box size="0.02 0.015 0.002" />
            </geometry>
        </collision>
        <visual>
            <origin rpy="0 0 0" xyz="-0.011 0 0" />
            <geometry>
                <box size="0.02 0.015 0.002" />
            </geometry>
            <material name="Black" />
        </visual>
    </link>
    <!-- Gazebo properties -->
    <gazebo reference="leg6_link2">
        <kp>100000.0</kp>
        <kd>1.0</kd>
        <mu1>100.0</mu1>
        <mu2>100.0</mu2>
        <material>Gazebo/Black</material>
    </gazebo>
    <!-- Fixed Joint 2 -->
    <joint name="leg6_fixed_joint2" type="fixed">
        <parent link="leg6_joint_link2" />
        <child link="leg6_link2" />
        <origin rpy="0 0 0" xyz="0 0 0" />
    </joint>
    <!-- Joint Link Geometry -->
    <link name="leg6_joint_link3">
        <inertial>
            <origin rpy="0 0 0" xyz="0 0 0" />
            <mass value="9.424777960769378e-05" />
            <inertia ixx="1.7907078125461817e-09" ixy="0" ixz="0" iyy="1.7907078125461817e-09" iyz="0" izz="4.712388980384689e-11" />
        </inertial>
        <collision>
            <origin rpy="0 1.5707963267948966 0.0" xyz="0 0 0" />
            <geometry>
                <cylinder length="0.015" radius="0.001" />
            </geometry>
        </collision>
        <visual>
            <origin rpy="0 1.5707963267948966 0.0" xyz="0 0 0" />
            <geometry>
                <cylinder length="0.015" radius="0.001" />
            </geometry>
            <material name="White" />
        </visual>
    </link>
    <!-- Gazebo properties -->
    <gazebo reference="leg6_joint_link3">
        <kp>100000.0</kp>
        <kd>1.0</kd>
        <mu1>100.0</mu1>
        <mu2>100.0</mu2>
        <material>Gazebo/White</material>
    </gazebo>
    <!-- Joint 3 -->
    <joint name="leg6_joint3" type="revolute">
        <parent link="leg6_link2" />
        <child link="leg6_joint_link3" />
        <origin rpy="0 0 0" xyz="-0.013500000000000002                 0.0085 0" />
        <dynamics damping="0.0" friction="0.0" />
        <limit effort="1.0" lower="-1.5707963267948966" upper="1.5707963267948966" velocity="1.0" />
        <axis xyz="1 0 0" />
    </joint>
    <transmission name="leg6_joint3_tran">
        <type>transmission_interface/SimpleTransmission</type>
        <joint name="leg6_joint3">
            <hardwareInterface>hardware_interface/EffortJointInterface</hardwareInterface>
        </joint>
        <actuator name="leg6_joint3_motor">
            <hardwareInterface>hardware_interface/EffortJointInterface</hardwareInterface>
            <mechanicalReduction>1</mechanicalReduction>
        </actuator>
    </transmission>
    <!-- Tarsus (Leg Link 3) Geometry -->
    <link name="leg6_link3">
        <inertial>
            <origin rpy="0 0 0" xyz="0 0 0" />
            <mass value="0.0018" />
            <inertia ixx="1.3559999999999997e-07" ixy="0" ixz="0" iyy="3.434999999999999e-08" iyz="0" izz="1.6874999999999997e-07" />
        </inertial>
        <collision>
            <origin rpy="0 0 0" xyz="0 0.016 0" />
            <geometry>
                <box size="0.015 0.03 0.002" />
            </geometry>
        </collision>
        <visual>
            <origin rpy="0 0 0" xyz="0 0.016 0" />
            <geometry>
                <box size="0.015 0.03 0.002" />
            </geometry>
            <material name="Orange" />
        </visual>
    </link>
    <!-- Gazebo properties -->
    <gazebo reference="leg6_link3">
        <kp>100000.0</kp>
        <kd>1.0</kd>
        <mu1>100.0</mu1>
        <mu2>100.0</mu2>
        <material>Gazebo/Orange</material>
    </gazebo>
    <!-- Fixed Joint 3 -->
    <joint name="leg6_fixed_joint3" type="fixed">
        <parent link="leg6_joint_link3" />
        <child link="leg6_link3" />
        <origin rpy="0 0 0" xyz="0 0 0" />
    </joint>
    <!-- Joint Link Geometry -->
    <link name="leg6_joint_link4">
        <inertial>
            <origin rpy="0 0 0" xyz="0 0 0" />
            <mass value="9.424777960769378e-05" />
            <inertia ixx="1.7907078125461817e-09" ixy="0" ixz="0" iyy="1.7907078125461817e-09" iyz="0" izz="4.712388980384689e-11" />
        </inertial>
        <collision>
            <origin rpy="0 1.5707963267948966 0.0" xyz="0 0 0" />
            <geometry>
                <cylinder length="0.015" radius="0.001" />
            </geometry>
        </collision>
        <visual>
            <origin rpy="0 1.5707963267948966 0.0" xyz="0 0 0" />
            <geometry>
                <cylinder length="0.015" radius="0.001" />
            </geometry>
            <material name="White" />
        </visual>
    </link>
    <!-- Gazebo properties -->
    <gazebo reference="leg6_joint_link4">
        <kp>100000.0</kp>
        <kd>1.0</kd>
        <mu1>100.0</mu1>
        <mu2>100.0</mu2>
        <material>Gazebo/White</material>
    </gazebo>
    <!-- Fixed Joint 4 (Foot Joint) -->
    <joint name="leg6_fixed_joint4" type="fixed">
        <parent link="leg6_link3" />
        <child link="leg6_joint_link4" />
        <origin rpy="0 0 0" xyz="0 0.032 0" />
    </joint>
    <joint name="leg6_coxa_joint" type="fixed">
        <parent link="thorax" />
        <child link="leg6_coxa" />
        <origin rpy="3.141592653589793 0 0" xyz="-0.022499999999999992 -0.01 0" />
    </joint>
    <gazebo>
        <plugin filename="libgazebo_ros_control.so" name="gazebo_ros_control">
            <robotNamespace>/millihex</robotNamespace>
        </plugin>
    </gazebo>
</robot>

